Workbook

Sheet requests
A1: Key | B1: ticketNo | C1: currentDateTime | D1: employeeId | E1: employeeName | F1: Plant | G1: userId | H1: jobType | I1: issueType | J1: อาการ | K1: ระบุ | L1: displayName | M1: pictureUrl | N1: request | O1: vncNumber | P1: Phonenum | Q1: FileAttachmentURL | R1: Status | S1: reply | T1: photo | U1: admin | V1: โลเคชั่นที่พบปัญหา
A2: 1 | B2: IT2410-001 | C2: 45572.373 | D2: 31043 | E2: {=XLOOKUP(D2,Employee!A:A,Employee!D:D)&" "&XLOOKUP(D2,Employee!A:A,Employee!E:E)} | F2: ICT | G2: Ueb33c059803cab01248e22ac9c846d8e | H2: ปัญหาโปรแกรม | I2: Microsoft Office (Word, Excel, Power Point) | J2: เปิดโปรแกรมไม่ได้ | L2: JOEY | M2: https://profile.line-scdn.net/0h3OUNMdD5bGB4N3zHDKUSHwhnbwpbRjVyVFQiU0xnZ1YWUH82VgZzUUtgZQBHAyJkXVBxBR1gMVl0JBsGZmGQVH8HMVFEACozXVAmhw | N2: ขณะนี้ notebook ไม่สามารถใช้งาน Excel, PowerPoint ได้ครับ รบกวนทาง IT มาดำเนินการ Reactivate โปรแกรมให้ด้วยนะครับ ขอบคุณครับ ฐานสุข QAC | O2: 192.168.102.206 | R2: ดำเนินการเรียบร้อย | S2: ReActivate | U2: IT03_วี | V2: ก่อนพัฒนา App
A3: 2 | B3: IT2410-002 | C3: 45572.38 | F3: JA | G3: U49989963d98a2bfb7f7a3a9e4d2b6021 | H3: ปัญหาเครือข่าย และอินเทอร์เน็ต | I3: อินเทอร์เน็ต | J3: ขอเชื่อมต่อ WiFi | L3: Armuayyy | M3: https://profile.line-scdn.net/0hjDlciQ_RNWtBGiXCuCxLFDFKNgFia2x5bnooXXEeal16eHNpbn9yXXQabVp9enA7ay8tD30SbVhNCUINX0zJX0YqaFp9LXM4ZH1_jA | N3: คอมไม่เชื่อมไวไฟ ลองเปิดเครื่องหรือ restart แล้วค่ะ | O3: 127.0.0.1 | Q3: https://drive.google.com/file/d/1rwCV6xwk_lQb2HYIWNrAnjMU4Cus-Gks/view?usp=drivesdk | R3: ดำเนินการเรียบร้อย | S3: ใส่รหัส Wifi ให้ใหม่ | U3: IT01_ดุ่ย | V3: ก่อนพัฒนา App
A4: 3 | B4: IT2410-003 | C4: 45572.428 | G4: c50f6693 | H4: ปัญหาเครือข่าย และอินเทอร์เน็ต | I4: อินเทอร์เน็ต | J4: ขอเชื่อมต่อ WiFi | N4: เชื่อมต่อ wifi ให้คุณโอ๋ | R4: ดำเนินการเรียบร้อย | S4: ใส่ Password wifi ให้ใหม่ คุณโอ๋ | U4: IT02_ก๊อต | V4: ก่อนพัฒนา App
A5: 4 | B5: IT2410-004 | C5: 45572.429 | G5: 296f6487 | H5: ขอสิทธิ์เข้าระบบ (ทำใบขอสิทธิ์) | I5: เปลี่ยนแปลงสิทธิ์ (คอมพิวเตอร์) | J5: ขอเปลี่ยนคอม | N5: เปลี่ยนให้คุณโชติกา ชัยมัง | R5: ดำเนินการเรียบร้อย | S5: Set Notebook เปลี่ยนให้คุณโชติกา ชัยมัง Mail wh02@comets | T5: requests_Images/IT2410-006.photo.035054.jpg | U5: IT02_ก๊อต | V5: ก่อนพัฒนา App
A6: 5 | B6: IT2410-005 | C6: 45572.456 | G6: e275f249 | H6: ปัญหาโปรแกรม | I6: Email | J6: ยกเลิกอีเมล | N6: ยกเลิก Account Email | R6: ดำเนินการเรียบร้อย | S6: ยกเลิก Account Email scm05@cometsintertrade.com | T6: requests_Images/IT2410-005.photo.033030.png | U6: IT02_ก๊อต | V6: ก่อนพัฒนา App
A7: 6 | B7: IT2410-006 | C7: 45572.472 | D7: 10594 | E7: {=XLOOKUP(D7,Employee!A:A,Employee!D:D)&" "&XLOOKUP(D7,Employee!A:A,Employee!E:E)} | F7: Comets | G7: U531c51794d7fcb3d37d6e65612cbcd50 | H7: ปัญหาเครือข่าย และอินเทอร์เน็ต | I7: อินเทอร์เน็ต | J7: ขอเชื่อมต่อ WiFi | L7: P | M7: https://profile.line-scdn.net/0hnb6r03nDMU0bCyRx8j9PMmtbMic4emhfN2V5f3kPai0iPiFJNGl5fy0MO3ghaCRMY2kqeCoKZy0XGEYrBV3NeRw7bHwnPHcePmx7qg | N7: โน๊ตบุ๊คเข้า Wi-Fi ไม่ได้ | O7: - | Q7: https://drive.google.com/file/d/1tbku5lE9v4YVYAXRBQGyn0jrtbOdfc_l/view?usp=drivesdk | R7: ดำเนินการเรียบร้อย | S7: นำ notebook เสียบสาย lan แล้ว reboot เครื่อง 1 ครั้ง ใช้งานได้ปกติ | U7: IT02_ก๊อต | V7: ก่อนพัฒนา App
A8: 7 | B8: IT2410-007 | C8: 45572.475 | D8: 11125 | E8: {=XLOOKUP(D8,Employee!A:A,Employee!D:D)&" "&XLOOKUP(D8,Employee!A:A,Employee!E:E)} | F8: Comets | G8: U012bcfe2879ba579bdb7a9e323eefbae | H8: คอมพิวเตอร์ | I8: Notebook | J8: ล็อกอินไม่ได้ | L8: Phosphate 🍂 | M8: https://profile.line-scdn.net/0ha-yF-K1PPgJUPy7sNWBAfSRvPWh3TmcQKg4hZjM3YmVhXyxTf1B4ZmE9NDNuW3wDKAwlYWU5YjBYLElkSmnCNlMPYzNoCHhRcVh05Q | N8: ไม่สามารถเข้ารหัสโน๊ตบุคได้ค่ะ เป็นของคนที่เข้ามาใหม่ค่ะ | R8: ดำเนินการเรียบร้อย | S8: ใส่ Password wi-fi และ New password Pumhq2024 | U8: IT02_ก๊อต | V8: ก่อนพัฒนา App
A9: 8 | B9: IT2410-008 | C9: 45572.483 | D9: 11021 | E9: {=XLOOKUP(D9,Employee!A:A,Employee!D:D)&" "&XLOOKUP(D9,Employee!A:A,Employee!E:E)} | F9: Comets | G9: Ufa11ba9a84ed39a0fad801a6e50027c9 | H9: ปัญหาโปรแกรม | I9: Microsoft Power Bi | J9: อื่นๆ (โปรดระบุ) | K9: รายชื่อผู้ใช้งาน | L9: Beam_i | M9: https://profile.line-scdn.net/0hRGbqVWxXDWhPCB2614xzFz9YDgJseVR6NzpDXS5bA1Fxak4_YWpBW3lYUFx3bUhrZmgQCSldVllDG3oOUV7xXEg4UFlzP0s7am9Hjw | N9: - ขอนำส่งรายชื่อผู้ใช้งาน MS365 : MS17@cometsintertrade0.microsoft.com เนื่องจากมีข้อมูล Sensitive Data และ Power BI อยู่ จึงเรียนแจ้งให้ทางไอทีพิจารณาผู้ใช้งานให้มีแค่ผู้เกี่ยวข้องและทีมบริหารค่ะ 1. เจกิตาน์ บุญเรือง Email : sls01@cometsintertrade.com 2.อภิญญา หนูช่วย Email : Sales03@cometsintertrade.com 3.พิมพ์ผกา ตั้งมั่น Email : sls02@cometsintertrade.com | R9: ดำเนินการเรียบร้อย | S9: ดำเนินการเรียบร้อยแล้วครับ | U9: IT02_ก๊อต | V9: ก่อนพัฒนา App
A10: 9 | B10: IT2410-009 | C10: 45572.567 | D10: 11101 | E10: {=XLOOKUP(D10,Employee!A:A,Employee!D:D)&" "&XLOOKUP(D10,Employee!A:A,Employee!E:E)} | F10: Comets | G10: U9ef7360853b8507b2a15b3c07ce532a3 | H10: ปัญหาโปรแกรม | I10: Microsoft Office (Word, Excel, Power Point) | J10: อื่นๆ (โปรดระบุ) | K10: รีเซ็ท Password | L10: 𝚖𝚞𝚙𝚒𝚖 | M10: https://profile.line-scdn.net/0htKyjy934K2RUEzv_R_JVGyRDKA53YnJ2fXdsBjQVcVBuIW5hfXFjAGUbIgZuc2o1KiJkUDQbd1RYAFwCSkXXUFMjdlVoJG03cXRhgw | N10: รบกวนreset password MS365 user：ms17 mi | O10: 192.168.202.91 | Q10: https://drive.google.com/file/d/1lP2RIcscHqMxM2GBiNyu_HffJFarJLCS/view?usp=drivesdk | R10: ดำเนินการเรียบร้อย | S10: Reset password เรียบร้อยแล้วครับ | U10: IT02_ก๊อต | V10: ก่อนพัฒนา App
A11: 10 | B11: IT2410-010 | C11: 45572.574 | D11: 10998 | E11: {=XLOOKUP(D11,Employee!A:A,Employee!D:D)&" "&XLOOKUP(D11,Employee!A:A,Employee!E:E)} | F11: Comets | G11: U012bcfe2879ba579bdb7a9e323eefbae | H11: ปัญหาโปรแกรม | I11: Email | J11: อื่นๆ (โปรดระบุ) | K11: ตั้งค่า signature | L11: Phosphate 🍂 | M11: https://profile.line-scdn.net/0ha-yF-K1PPgJUPy7sNWBAfSRvPWh3TmcQKg4hZjM3YmVhXyxTf1B4ZmE9NDNuW3wDKAwlYWU5YjBYLElkSmnCNlMPYzNoCHhRcVh05Q | N11: เปลี่ยน signature ในเมล์ไม่ได้ค่ะ | O11: 192.168.202.192 | R11: ดำเนินการเรียบร้อย | S11: ใส่ signature outlook | T11: requests_Images/IT2410-012.photo.070949.png | U11: IT02_ก๊อต | V11: ก่อนพัฒนา App
A12: 11 | B12: IT2410-011 | C12: 45572.649 | G12: 57541fb6 | H12: ปัญหาโปรแกรม | I12: Microsoft Power Bi | J12: ล็อกอิน License | N12: Login power bi | R12: ดำเนินการเรียบร้อย | S12: Login power bi คุณพลอย QC | T12: requests_Images/IT2410-013.photo.083517.jpg | U12: IT02_ก๊อต | V12: ก่อนพัฒนา App
A13: 12 | B13: IT2410-012 | C13: 45572.653 | F13: Comets | G13: U898ef64932b1971d3c511d24772b7760 | H13: ปริ้นเตอร์ | I13: ปริ้นเตอร์อื่นๆ | J13: ปริ้นไม่ออก | L13: เพชร | M13: https://profile.line-scdn.net/0h6qxujkzLaV5VDHlKmMIXISVcajR2fTBMeD8nOmZYM2s_b34JcTkkOjIOMWxrOygPf2J2bWYLYDxZHx44S1qValI8NG9pOy8NcGsjuQ | N13: 1. เครื่องปริ้นสติกเกอร์ใช้งานไม่ได้ 2. เครื่องปริ้นเอกสารกดสั่งปริ้นแล้ว แต่ไม่ขึ้นที่หน้าจอค่ะ | O13: 192.168.202.237 | Q13: https://drive.google.com/file/d/129p5oW90pG3kwezqvM0bADfj1SS85RYC/view?usp=drivesdk | R13: ดำเนินการเรียบร้อย | S13: Add printer label, set account printer 1 | U13: IT02_ก๊อต | V13: ก่อนพัฒนา App
A14: 13 | B14: IT2410-013 | C14: 45572.669 | G14: 4f20285d | H14: ขอสิทธิ์เข้าระบบ (ทำใบขอสิทธิ์) | I14: เปลี่ยนแปลงสิทธิ์ (Driveshare) | J14: ขอเพิ่มสิทธิ์ไฟล์กลาง | N14: Map drive express ของ vps | R14: ดำเนินการเรียบร้อย | S14: ดำเนินการ Map drive express ของ vps และสั่งซื้อเครื่องสำรองไฟใช้งาน | T14: requests_Images/IT2410-013.photo.035736.jpg | U14: IT02_ก๊อต | V14: ก่อนพัฒนา App
A15: 14 | B15: IT2410-014 | C15: 45572.673 | G15: 6ba3d233 | H15: ปัญหาโปรแกรม | I15: ติดตั้งโปรแกรม | J15: ระบุโปรแกรม | K15: โปรแกรมบัญชี | N15: เพิ่มโปรแกรมโปรแกรมบัญชี | R15: ดำเนินการเรียบร้อย | S15: เพิ่มโปรแกรมโปรแกรมบัญชี express ของ vps Notebook คุณเจี๊ยบ | T15: requests_Images/IT2410-014.photo.033843.jpg | U15: IT02_ก๊อต | V15: ก่อนพัฒนา App
A16: 15 | B16: IT2410-015 | C16: 45573.338 | D16: 30398 | E16: ธัญญรัตน์ หิรัญวงษ์ | F16: ICT | G16: U9e19abc838c7c00bd4995b0f827245bd | H16: คอมพิวเตอร์ | I16: Notebook | J16: อื่นๆ (โปรดระบุ) | K16: Touch Pad ใช้งานไม่ได้ | L16: WaWa 와와 🍀🐰🐻 | M16: https://profile.line-scdn.net/0hpt5JLRQTL1sYMz3IrD1RJGhjLDE7QnZJNFVnbXo0IWogUWkIPVQybysyIWkkBGwPM1dgaiU7eG4UIFg9BmXTbx8DcmokBGkIPVRlvA | N16: Touch Pad เครื่อง Lenovo Notebook ใช้งานไม่ได้ | O16: 192.168.102.178 | R16: ดำเนินการเรียบร้อย | S16: อัพเดทไดร์เวอร์ | U16: IT03_วี | V16: ก่อนพัฒนา App
A17: 16 | B17: IT2410-016 | C17: 45573.372 | D17: 20032 | E17: {=XLOOKUP(D17,Employee!A:A,Employee!D:D)&" "&XLOOKUP(D17,Employee!A:A,Employee!E:E)} | F17: JA | G17: Uad5c175c02aae142cc13cc39e7a5e76f | H17: ปัญหาเครือข่าย และอินเทอร์เน็ต | I17: อินเทอร์เน็ต | J17: ขอเชื่อมต่อ WiFi | L17: Benz | M17: https://profile.line-scdn.net/0hu8BXJA9QKhdvITprTZtUaB9xKX1MUHMFE0U1dAogIXMHEGlBRUJgeFkoICNREGVDFBVldwl2ci5jMl1xcXfWI2gRdyZTFmxESkZg8A | N17: เครื่องเชื่อมต่อ wifi บริษัทไม่ได้ครับ | O17: 127.0.0.1 | Q17: https://drive.google.com/file/d/1_yYdnjH5pbVGObUj8FXLWYtbynClzaYn/view?usp=drivesdk | R17: ดำเนินการเรียบร้อย | S17: ใส่ Password wifi ให้ใหม่ | U17: IT02_ก๊อต | V17: ก่อนพัฒนา App
A18: 17 | B18: IT2410-017 | C18: 45573.401 | D18: 11116 | E18: {=XLOOKUP(D18,Employee!A:A,Employee!D:D)&" "&XLOOKUP(D18,Employee!A:A,Employee!E:E)} | F18: Comets | G18: U4a07ad3a08444cf73353bad165aa7f89 | H18: คอมพิวเตอร์ | I18: Notebook | J18: ล็อคอินไม่ได้ | L18: PCM06_Fyne | M18: https://profile.line-scdn.net/0h3oXNBCvFbEB1N3zGSMESPwVnbypWRjVSCwN0LkgyZyJIVyMVDVglJEY1YCdIBCJFC1lxc0NiZXZ5JBsma2GQdHIHMXFJACoTUFAmpw | N18: ล็อคอินไม่ได้ | Q18: https://drive.google.com/file/d/15zb604qu2Nwp0edWXHYfe6FhsaIZlD3z/view?usp=drivesdk | R18: ดำเนินการเรียบร้อย | S18: Enable account server AD | U18: IT02_ก๊อต | V18: ก่อนพัฒนา App
A19: 18 | B19: IT2410-018 | C19: 45573.401 | D19: 31043 | E19: {=XLOOKUP(D19,Employee!A:A,Employee!D:D)&" "&XLOOKUP(D19,Employee!A:A,Employee!E:E)} | F19: ICT | G19: Ueb33c059803cab01248e22ac9c846d8e | H19: ปริ้นเตอร์ | I19: ปริ้นเตอร์อื่นๆ | J19: ปริ้นไม่ออก | L19: JOEY | M19: https://profile.line-scdn.net/0h3OUNMdD5bGB4N3zHDKUSHwhnbwpbRjVyVFQiU0xnZ1YWUH82VgZzUUtgZQBHAyJkXVBxBR1gMVl0JBsGZmGQVH8HMVFEACozXVAmhw | N19: ขอแจ้งเรื่องเครื่องปริ้นท์ในห้อง QAC ไม่สามารถปริ้นท์งานได้ เบื้องต้นคาดว่ามีปัญหาที่ตัวดึงกระดาษครับ | R19: ดำเนินการเรียบร้อย | S19: ตรวจสอบมีของติดด้านในตัวดึงกระดาษ | U19: IT03_วี | V19: ก่อนพัฒนา App
A20: 19 | B20: IT2410-019 | C20: 45573.446 | D20: 10162 | E20: {=XLOOKUP(D20,Employee!A:A,Employee!D:D)&" "&XLOOKUP(D20,Employee!A:A,Employee!E:E)} | F20: Comets | G20: Ub68788fdfe8d25d25663b7c76638d629 | H20: ขอสิทธิ์เข้าระบบ (ทำใบขอสิทธิ์) | I20: ขอใช้งาน VPN | L20: Yui🌈☀️ | M20: https://profile.line-scdn.net/0hN_0bWV3NEXAdGwHhACJvD21LEho-akhiNCkMRiAbSUZ0LVEmN35XFXhJT0MmLwYkN3QLEyEcGEARCGYWA03tRBorTEEhLFcjOHxblw | N20: เปลี่ยนเครื่องใหม่ต้องการให้เพิ่ม VPN เพื่อใช่งานนอกสถานที่ได้ค่ะ | O20: 112.248 | R20: ดำเนินการเรียบร้อย | S20: Set VPN ใช้งาน | T20: requests_Images/IT2410-021.photo.035147.png | U20: IT02_ก๊อต | V20: ก่อนพัฒนา App
A21: 20 | B21: IT2410-020 | C21: 45573.443 | D21: 10990 | E21: {=XLOOKUP(D21,Employee!A:A,Employee!D:D)&" "&XLOOKUP(D21,Employee!A:A,Employee!E:E)} | F21: Comets | G21: U4f92c5fb937d134192fbe7fe519b545e | H21: อุปกรณ์ไอที | I21: คีย์บอร์ด | J21: อื่นๆ (โปรดระบุ) | K21: เชื่อมคีย์บอร์ดไม่ได้ | L21: กอตอ | M21: https://profile.line-scdn.net/0hyyZv739gJlZ3DzcyF1tYKQdfJTxUfn9EWGg7NUdfKzYeajVXWDs9Y0cIfWMYO2dTW2lrNREIKG97HFEwaVnaYnA_e2dLOGAFUmhssQ | N21: เชื่อมบูลทูธของkeyboardsไม่ได้ เนื่องจากไม่มีตัวรับสัญญาณ | O21: 112.76 | R21: ดำเนินการเรียบร้อย | S21: ส่ง USB Set all-in-one ให้ USER | U21: IT02_ก๊อต | V21: ก่อนพัฒนา App
A22: 21 | B22: IT2410-021 | C22: 45573.461 | D22: 10162 | E22: {=XLOOKUP(D22,Employee!A:A,Employee!D:D)&" "&XLOOKUP(D22,Employee!A:A,Employee!E:E)} | F22: Comets | G22: Ub68788fdfe8d25d25663b7c76638d629 | H22: ปริ้นเตอร์ | I22: ปริ้นเตอร์อื่นๆ | J22: เพิ่มเครื่องปริ้น | L22: Yui🌈☀️ | M22: https://profile.line-scdn.net/0hN_0bWV3NEXAdGwHhACJvD21LEho-akhiNCkMRiAbSUZ0LVEmN35XFXhJT0MmLwYkN3QLEyEcGEARCGYWA03tRBorTEEhLFcjOHxblw | N22: ขอปริ้นเครื่องปริ้น EPSON LQ-310 **VNC112.76 เครื่องหลัก** | O22: 112.248 | R22: ดำเนินการเรียบร้อย | S22: Add share printer EPSON LQ-310 จากเครื่อง CMICT087 | U22: IT02_ก๊อต | V22: ก่อนพัฒนา App
A23: 22 | B23: IT2410-022 | C23: 45573.5 | D23: 90216 | E23: {=XLOOKUP(D23,Employee!A:A,Employee!D:D)&" "&XLOOKUP(D23,Employee!A:A,Employee!E:E)} | F23: Comets | G23: U898ef64932b1971d3c511d24772b7760 | H23: ปัญหาโปรแกรม | I23: Email | J23: เปิดใช้งานอีเมล | L23: เพชร | M23: https://profile.line-scdn.net/0h6qxujkzLaV5VDHlKmMIXISVcajR2fTBMeD8nOmZYM2s_b34JcTkkOjIOMWxrOygPf2J2bWYLYDxZHx44S1qValI8NG9pOy8NcGsjuQ | N23: เพิ่มเมล pcm 31 ให้เครื่องพี่กันหน่อยค่ะ | O23: 192.168.202.237 | R23: ดำเนินการเรียบร้อย | S23: Set account email pcm31@comets | T23: requests_Images/IT2410-024.photo.063248.png | U23: IT02_ก๊อต | V23: ก่อนพัฒนา App
A24: 23 | B24: IT2410-023 | C24: 45573.525 | D24: 11116 | E24: {=XLOOKUP(D24,Employee!A:A,Employee!D:D)&" "&XLOOKUP(D24,Employee!A:A,Employee!E:E)} | F24: Comets | G24: U4a07ad3a08444cf73353bad165aa7f89 | H24: ปริ้นเตอร์ | I24: ปริ้นเตอร์อื่นๆ | J24: เพิ่มเครื่องปริ้น | L24: PCM06_Fyne | M24: https://profile.line-scdn.net/0h3oXNBCvFbEB1N3zGSMESPwVnbypWRjVSCwN0LkgyZyJIVyMVDVglJEY1YCdIBCJFC1lxc0NiZXZ5JBsma2GQdHIHMXFJACoTUFAmpw | N24: 1.รบกวนset up printing1 2. เพิ่ม folder pcm06_11116 ใน ไดร์ฟ Comets procurement ให้ด้วยค่ะ | R24: ดำเนินการเรียบร้อย | S24: Set account printer, Map drive pcm06_11116_Khuanruethai | T24: requests_Images/IT2410-025.photo.062221.png | U24: IT02_ก๊อต | V24: ก่อนพัฒนา App
A25: 24 | B25: IT2410-024 | C25: 45573.595 | D25: 11045 | E25: {=XLOOKUP(D25,Employee!A:A,Employee!D:D)&" "&XLOOKUP(D25,Employee!A:A,Employee!E:E)} | F25: Comets | G25: U398fba6097cdb8f5afd0a164fad81ee9 | H25: ปริ้นเตอร์ | I25: ปริ้นเตอร์ | J25: ขอเช็คสิทธิ์ปริ้นเตอร์ | L25: Saiaew_r | M25: https://profile.line-scdn.net/0hNCXRXjH5EWx1KwHVk7ZvEwV7EgZWWkh-DkRcDxUiTQlAT1JuXEwMAxciRg8YTFE9URgKDEMiGg95OGYKa33tWHIbTF1JHFc_UExbiw | N25: ติดต่อเจ้าหน้าที่ปริ้นเอกสารไม่ได้ ต้องการเช็คสิทธิ์ปริ้นงาน | O25: 78 | R25: ดำเนินการเรียบร้อย | S25: ตรวจสอบ Print Black Impressions 29/300 | T25: requests_Images/IT2410-026.photo.072156.png | U25: IT02_ก๊อต | V25: ก่อนพัฒนา App
A26: 25 | B26: IT2410-025 | C26: 45573.6 | G26: 990cc7f4 | H26: คอมพิวเตอร์ | I26: Notebook | J26: อื่นๆ (โปรดระบุ) | K26: เซ็ทคอมพิวเตอร์ | N26: set computer คุณนะ | R26: ดำเนินการเรียบร้อย | S26: set computer คุณนะ เปลี่ยนจาก macos เป็น computer CMICT085 | U26: IT02_ก๊อต | V26: ก่อนพัฒนา App
A27: 26 | B27: IT2410-026 | C27: 45573.649 | D27: 10162 | E27: {=XLOOKUP(D27,Employee!A:A,Employee!D:D)&" "&XLOOKUP(D27,Employee!A:A,Employee!E:E)} | F27: Comets | G27: Ub68788fdfe8d25d25663b7c76638d629 | H27: ปัญหาโปรแกรม | I27: ติดตั้งโปรแกรม | J27: ระบุโปรแกรม | K27: โปรแกรม Express | L27: Yui🌈☀️ | M27: https://profile.line-scdn.net/0hN_0bWV3NEXAdGwHhACJvD21LEho-akhiNCkMRiAbSUZ0LVEmN35XFXhJT0MmLwYkN3QLEyEcGEARCGYWA03tRBorTEEhLFcjOHxblw | N27: ขอเพิ่มโปรแกรม Express บริษัทขายดี ลงเครื่องค่ะ | O27: 112.248 | R27: ดำเนินการเรียบร้อย | S27: Add express ict ใช้งาน | T27: requests_Images/IT2410-028.photo.084558.png | U27: IT02_ก๊อต | V27: ก่อนพัฒนา App
A28: 27 | B28: IT2410-027 | C28: 45573.659 | G28: caed2e6a | H28: คอมพิวเตอร์ | I28: Macbook | J28: อื่นๆ (โปรดระบุ) | K28: ล็อคอิน Mac OS ไม่ได้ | N28: login Macos ไม่ได้ | R28: ดำเนินการเรียบร้อย | S28: User login Macos ไม่ได้ password ไม่ถูกต้อง repassword ใหม่ | U28: IT02_ก๊อต | V28: ก่อนพัฒนา App
A29: 28 | B29: IT2410-028 | C29: 45573.687 | D29: 11021 | E29: {=XLOOKUP(D29,Employee!A:A,Employee!D:D)&" "&XLOOKUP(D29,Employee!A:A,Employee!E:E)} | F29: Comets | G29: Ufa11ba9a84ed39a0fad801a6e50027c9 | H29: ปัญหาโปรแกรม | I29: Email | J29: อีเมลเต็ม (แบ็คอัพอีเมล) | L29: Beam_i | M29: https://profile.line-scdn.net/0hRGbqVWxXDWhPCB2614xzFz9YDgJseVR6NzpDXS5bA1Fxak4_YWpBW3lYUFx3bUhrZmgQCSldVllDG3oOUV7xXEg4UFlzP0s7am9Hjw | N29: 1.ติดตั้งโปรแกรม Power BI 2.Backup mail | O29: 192.168.203.23 | R29: ดำเนินการเรียบร้อย | S29: ทำการติดตั้งเรียบร้อยแล้ว | U29: IT01_ดุ่ย | V29: ก่อนพัฒนา App
A30: 29 | B30: IT2410-029 | C30: 45574.413 | D30: 10485 | E30: {=XLOOKUP(D30,Employee!A:A,Employee!D:D)&" "&XLOOKUP(D30,Employee!A:A,Employee!E:E)} | F30: Comets | G30: Uee02c5e5492c8399c0f0e2ba134eb675 | H30: คอมพิวเตอร์ | I30: iMac | J30: อื่นๆ (โปรดระบุ) | K30: ยืมเครื่อง iMac ส่งไป ICT | L30: AUMIRABLE | M30: https://profile.line-scdn.net/0htg4tlwjGK0gZDTtcnXVVN2ldKCI6fHJaNWpifSgPdX8hNW9OMzg3Jy9ZJ3slP2wfYT5jKykIJn0VHlwuB1vXfB49dnklOm0bPGphrw | N30: ขอยืมเครื่อง iMac ไปสลับกับเครื่องโน๊ตบุคของน้องกิ่ง mkt ict | Q30: https://drive.google.com/file/d/1s9ELAnBO3OZbywSE3aA8ZtognpdjC-_5/view?usp=drivesdk | R30: ดำเนินการเรียบร้อย | S30: นำส่ง iMac ไป ict ที่คุณกิ่ง mkt ใช้งาน | T30: requests_Images/IT2410-031.photo.033446.jpg | U30: IT01_ดุ่ย | V30: ก่อนพัฒนา App
A31: 30 | B31: IT2410-030 | C31: 45574.415 | D31: 11116 | E31: {=XLOOKUP(D31,Employee!A:A,Employee!D:D)&" "&XLOOKUP(D31,Employee!A:A,Employee!E:E)} | F31: Comets | G31: U4a07ad3a08444cf73353bad165aa7f89 | H31: ปัญหาโปรแกรม | I31: PDF | J31: ตั้งค่าโปรแกรม | L31: PCM06_Fyne | M31: https://profile.line-scdn.net/0h3oXNBCvFbEB1N3zGSMESPwVnbypWRjVSCwN0LkgyZyJIVyMVDVglJEY1YCdIBCJFC1lxc0NiZXZ5JBsma2GQdHIHMXFJACoTUFAmpw | N31: Sign in PDF ไม่ได้ | R31: ดำเนินการเรียบร้อย | S31: add bookmark this tab website sap ดำเนินการเสร็จเรียบร้อยแล้ว, Sign in PDF ไม่ได้ ใช้งานแก้ไข (รอใบขอสิทธิ์ใช้งาน) | U31: IT02_ก๊อต | V31: ก่อนพัฒนา App
A32: 31 | B32: IT2410-031 | C32: 45574.443 | D32: 11084 | E32: {=XLOOKUP(D32,Employee!A:A,Employee!D:D)&" "&XLOOKUP(D32,Employee!A:A,Employee!E:E)} | F32: Comets | G32: Uf549acc1ece2b7a22b35dbbe9d6ef113 | H32: ปัญหาโปรแกรม | I32: โปรแกรมอื่นๆ (โปรดระบุ) | J32: โปรดระบุ | L32: PUR06_โบว์ | M32: https://profile.line-scdn.net/0h8ni4YV7GZ0FETXe2hh0ZPjQdZCtnPD5TPC0hIyQYPiZ4L3RFPXkpJnUaP3IrdCAUbCJ8JyFIP3hIXhAnWhubdUN9OnB4eiESYSotpg | N32: หน้าจอกดไม่ได้ | O32: 100002026 | Q32: https://drive.google.com/file/d/1v-mdIHjnNJfpH_CbW51pY45ilJsSugB4/view?usp=drivesdk | R32: ดำเนินการเรียบร้อย | S32: Reset password user บน AD | U32: IT02_ก๊อต | V32: ก่อนพัฒนา App
A33: 32 | B33: IT2410-032 | C33: 45574.465 | D33: 11125 | E33: {=XLOOKUP(D33,Employee!A:A,Employee!D:D)&" "&XLOOKUP(D33,Employee!A:A,Employee!E:E)} | F33: Comets | G33: U898ef64932b1971d3c511d24772b7760 | H33: ขอสิทธิ์เข้าระบบ (ทำใบขอสิทธิ์) | I33: เปลี่ยนแปลงสิทธิ์ (Driveshare) | J33: ขอเพิ่มสิทธิ์ไฟล์กลาง | L33: เพชร | M33: https://profile.line-scdn.net/0h6qxujkzLaV5VDHlKmMIXISVcajR2fTBMeD8nOmZYM2s_b34JcTkkOjIOMWxrOygPf2J2bWYLYDxZHx44S1qValI8NG9pOy8NcGsjuQ | N33: แมทไดร์ฟ Admin ให้ PCM 33 | O33: 192.168.203.68 | R33: ดำเนินการเรียบร้อย | S33: Map drive 4_PCM PCM32_admin เพื่อใช้งาน share drive ของ admin ตามใบขอสิทธิ์ใช้งาน | T33: requests_Images/IT2410-034.photo.035752.jpg | U33: IT02_ก๊อต | V33: ก่อนพัฒนา App
A34: 33 | B34: IT2410-033 | C34: 45574.468 | D34: 11107 | E34: {=XLOOKUP(D34,Employee!A:A,Employee!D:D)&" "&XLOOKUP(D34,Employee!A:A,Employee!E:E)} | F34: Comets | G34: Ub591751768536a3d75c1394b83ffa9c8 | H34: ปัญหาโปรแกรม | I34: PDF | J34: ตั้งค่าโปรแกรม | L34: Pim Patcharapan | M34: https://profile.line-scdn.net/0hySBEIswKJnxvPDb7aEZYAx9sJRZMTX9uRwg5Tw45eBwHBWUvFA1sEghsf0tVDzN_Ewg8SQhuek1jL1EacWraSGgMe01TC2AvSltsmw | N34: PDF ไม่สามารถพิมพ์เป็นภาษาไทยได้ | O34: 192.168.203.74 | R34: ดำเนินการเรียบร้อย | S34: เปิด edit adobe reader | T34: requests_Images/IT2410-035.photo.042816.jpg | U34: IT02_ก๊อต | V34: ก่อนพัฒนา App
A35: 34 | B35: IT2410-034 | C35: 45574.549 | D35: 30315 | E35: {=XLOOKUP(D35,Employee!A:A,Employee!D:D)&" "&XLOOKUP(D35,Employee!A:A,Employee!E:E)} | F35: ICT | G35: U284cb996db2131536b5800d4b800c29b | H35: ปัญหาเครือข่าย และอินเทอร์เน็ต | I35: Driveshare (ไฟล์กลาง) | J35: ไดรฟ์ไฟล์กลางหาย | L35: Dow💫45 | M35: https://profile.line-scdn.net/0hYss_zqm4BlxeJhPk1a14Iy52BTZ9V19OJUQaP2olD2thRkJdJkYdPml1DT9hEEAJd0BPOT4kX2lSNXE6QHD6aFkWW21iEUAPe0FMuw | N35: ข้อมูลในไฟล์กลางหาย หลังเน็ตหลุดทุกครั้้ง | O35: 192.168.103.59 | Q35: https://drive.google.com/file/d/10DbNU-IE98SMrsB56xpGetcEp2HubBBy/view?usp=drivesdk | R35: ดำเนินการเรียบร้อย | S35: ยกเลิก Map Drive เดิม และทำ Map Drive ใหม่ | U35: IT03_วี | V35: ก่อนพัฒนา App
A36: 35 | B36: IT2410-035 | C36: 45574.558 | D36: 11125 | E36: {=XLOOKUP(D36,Employee!A:A,Employee!D:D)&" "&XLOOKUP(D36,Employee!A:A,Employee!E:E)} | F36: Comets | G36: U898ef64932b1971d3c511d24772b7760 | H36: ปริ้นเตอร์ | I36: Printer 1 | J36: ปริ้นไม่ออก | L36: เพชร | M36: https://profile.line-scdn.net/0h6qxujkzLaV5VDHlKmMIXISVcajR2fTBMeD8nOmZYM2s_b34JcTkkOjIOMWxrOygPf2J2bWYLYDxZHx44S1qValI8NG9pOy8NcGsjuQ | N36: เครื่องปริ้นใช้ไม่ได้ค่ะ | O36: 192.168.203.68 | R36: ดำเนินการเรียบร้อย | S36: Set account printer ใช้งาน | T36: requests_Images/IT2410-037.photo.064013.png | U36: IT02_ก๊อต | V36: ก่อนพัฒนา App
A37: 36 | B37: IT2410-036 | C37: 45574.561 | D37: 31038 | E37: {=XLOOKUP(D37,Employee!A:A,Employee!D:D)&" "&XLOOKUP(D37,Employee!A:A,Employee!E:E)} | F37: ICT | G37: U7f1aca7d27b3ac8b9a77482617b703a0 | H37: ปัญหาโปรแกรม | I37: ติดตั้งโปรแกรม | J37: ระบุโปรแกรม | K37: โปรแกรม GX Works | L37: Shinnies | M37: https://profile.line-scdn.net/0h946I1eq3ZhsbMHQ8lPQYZGtgZXE4QT8JPwUgens1MS0hA3VNZ1QrKSkyb3kiByYePlUteC1nbXgXIxF9BWaaLxwAOyonByBIPlcs_A | N37: ติดตั้งโปรแกรม GX Works บนโนีตบุ๊คบริษัท | O37: 192.168.103.6 | R37: ดำเนินการเรียบร้อย | S37: ดำเนินการติดตั้งโปรแกรม GX Works | U37: IT03_วี | V37: ก่อนพัฒนา App
A38: 37 | B38: IT2410-037 | C38: 45574.607 | D38: 31043 | E38: {=XLOOKUP(D38,Employee!A:A,Employee!D:D)&" "&XLOOKUP(D38,Employee!A:A,Employee!E:E)} | F38: ICT | G38: Ueb33c059803cab01248e22ac9c846d8e | H38: คอมพิวเตอร์ | I38: Notebook | J38: ล็อคอินไม่ได้ | L38: JOEY | M38: https://profile.line-scdn.net/0h3OUNMdD5bGB4N3zHDKUSHwhnbwpbRjVyVFQiU0xnZ1YWUH82VgZzUUtgZQBHAyJkXVBxBR1gMVl0JBsGZmGQVH8HMVFEACozXVAmhw | N38: เนื่องจากไม่สามารถเข้าใช้งาน notebook ได้ เพราะรหัสเข้าใช้งานหมดอายุครับ รบกวน IT ดำเนินการแก้ไขให้หน่อยครับ ขอบคุณครับ | R38: ดำเนินการเรียบร้อย | S38: แนะนำการตั้งรหัสใหม่ให้ User สามารถตั้งรหัสเองได้เลย | U38: IT03_วี | V38: ก่อนพัฒนา App
A39: 38 | B39: IT2410-038 | C39: 45574.626 | F39: Comets | G39: Ub591751768536a3d75c1394b83ffa9c8 | H39: ขอสิทธิ์เข้าระบบ (ทำใบขอสิทธิ์) | I39: พนักงานใหม่ | J39: เซ็ทอัพคอมพิวเตอร์ | L39: Pim Patcharapan | M39: https://profile.line-scdn.net/0hySBEIswKJnxvPDb7aEZYAx9sJRZMTX9uRwg5Tw45eBwHBWUvFA1sEghsf0tVDzN_Ewg8SQhuek1jL1EacWraSGgMe01TC2AvSltsmw | N39: Set เครื่องพนักงานใหม่ | Q39: https://drive.google.com/file/d/1FG1MeNCQ1vyuAHabl96WdzLEVWu-pi8g/view?usp=drivesdk | R39: ดำเนินการเรียบร้อย | S39: Set เครื่องพนักงานใหม่เสร็จเรียบร้อย รอส่งมอบวันที่ 15/10/24 | U39: IT02_ก๊อต | V39: ก่อนพัฒนา App
A40: 39 | B40: IT2410-039 | C40: 45574.659 | D40: 31110 | E40: {=XLOOKUP(D40,Employee!A:A,Employee!D:D)&" "&XLOOKUP(D40,Employee!A:A,Employee!E:E)} | F40: ICT | G40: U0ff020f5a20fc80819822365855a34ae | H40: ขอสิทธิ์เข้าระบบ (ทำใบขอสิทธิ์) | I40: เปลี่ยนแปลงสิทธิ์ (Driveshare) | J40: ขอเพิ่มสิทธิ์ไฟล์กลาง | L40: Kookkai | M40: https://profile.line-scdn.net/0hasdY5MuLPlxJIC2UgvBAIzlwPTZqUWdOMBUhPngoY2ghE3wLY0N5PywjYTkgRXsOYxMlPn8mNW1FM0k6V3bCaE4QY211F3gPbEd0uw | N40: ขอสิทธิ์เข้าไดร์ฟ Purchase | O40: 192.168.102.197 | Q40: https://drive.google.com/file/d/17F9eou9sC4kOHVf6uha2gHvCIt1Rx4b_/view?usp=drivesdk | R40: ดำเนินการเรียบร้อย | S40: เพิ่มไดร์ฟกลาง Purchase (Read only) | U40: IT03_วี | V40: ก่อนพัฒนา App
...

Sheet คู่มือ
A1: คู่มือ | B1: คู่มือ2
A2: คู่มือ_Images/3.คู่มือ.104438.jpg | B2: คู่มือ_Images/3.คู่มือ2.104438.jpg

Sheet Employee
A1: รหัสพนักงาน | B1: Password | C1: สังกัด | D1: ชื่อ(ไทย) | E1: นามสกุล(ไทย) | F1: (ไทย) ฝ่าย | G1: (ไทย) แผนก | H1: ตำแหน่ง(ไทย) | I1: ชื่อเล่น | J1: วันเริ่มงาน | K1: วันที่ออก | L1: อีเมล | M1: เบอร์โทร
A2: Admin | B2: 1234 | C2: Admin | D2: IT | E2: Admin | F2: Admin | G2: Admin | H2: Admin | I2: Admin
A3: 10001 | B3: 10001 | C3: Comets | D3: วรพล | E3: พิบูลย์สวัสดิ์ | F3: บริหาร | G3: A10_บริหาร | H3: A19_ประธานบริษัท | I3: คุณอู๋ | J3: 34239
A4: 10077 | B4: 10077 | C4: Comets | D4: ศุกร์วัน | E4: แซ่เจน | F4: บริหาร | G4: B21_เลขานุการ | H4: เลขานุการ | I4: ฟุ้ง | J4: 42373 | K4: 43856
A5: 10121 | B5: 10121 | C5: Comets | D5: ไชยวุฒิ | E5: เอี่ยมผ่องใส | F5: บริหาร | G5: A01 Executive | H5: รองประธานฝ่ายปฏิบัติการ | I5: พี่วุฒิ | J5: 42739 | K5: 43399
A6: 10002 | B6: 10002 | C6: Comets | D6: ศลิษา | E6: พิบูลย์สวัสดิ์ | F6: บริหาร | G6: A10_บริหาร | H6: A18_ประธานบริหาร | I6: คุณจุ๋ม | J6: 34239
A7: 10250 | B7: 10250 | C7: Comets | D7: สืบวงศ์ | E7: โรจน์วานิช | F7: บริหาร | G7: A01 Executive | H7: ประธานฝ่ายการตลาด | I7: สืบ | J7: 43040 | K7: 43185
A8: 10434 | B8: 10434 | C8: Comets | D8: ณัฐรินทร์ | E8: ตาลทอง | F8: บริหาร | G8: A01 Executive | H8: กรรมการบริษัท | I8: คุณเอ | J8: 43357 | K8: 43550
A9: 10435 | B9: 10435 | C9: Comets | D9: รุ่งราตรี | E9: เลิศพงศ์ไพศาล | F9: บริหาร | G9: A01 Executive | H9: - | I9: พี่ต้อม | J9: 43357 | K9: 43550
A10: 10436 | B10: 10436 | C10: Comets | D10: ชฎาธาร | E10: กันหอม | F10: บริหาร | G10: A01 Executive | H10: - | I10: พี่กุ้ง | J10: 43357 | K10: 43550
A11: 10450 | B11: 10450 | C11: Comets | D11: สืบสันติ์ | E11: ธนวิโรจน์กุล | F11: บริหาร | G11: A01 Executive | H11: - | I11: โบ๊ท | J11: 43389 | K11: 43550
A12: 10474 | B12: 10474 | C12: Comets | D12: สฤษฎ์รัช | E12: พิบูลย์สวัสดิ์ | F12: บริหาร | G12: A10_บริหาร | H12: B65_ผช.ผู้จัดการฝ่ายสารสนเทศ | I12: คุณโอม | J12: 43466 | K12: 44377
A13: 10483 | B13: 10483 | C13: Comets | D13: มานะ | E13: เตียงตระกูลทอง | F13: บริหาร | G13: A10_บริหาร | H13: A19_ที่ปรึกษาบริษัท | I13: คุณมานะ | J13: 43466 | K13: 44043
A14: 10120 | B14: 10120 | C14: Comets | D14: ณัทญา | E14: แซ่เตียว | F14: ฝ่ายการตลาด | G14: B14_ขับรถส่วนกลาง | H14: F12_เจ้าหน้าที่ผลิต อาวุโส | I14: ซู | J14: 42739 | K14: 43734
A15: 10190 | B15: 10190 | C15: Comets | D15: ยลรดี | E15: เปรมสมาน | F15: ฝ่ายการตลาด | G15: B21_เลขานุการ | H15: เลขานุการ | I15: ส้ม | J15: 42927 | K15: 43887
A16: 10485 | B16: 10485 | C16: Comets | D16: อุมารัตน์ | E16: ตฤษณารมย์ | F16: ฝ่ายการตลาด | G16: A21_การตลาด | H16: B26_ผช.ผู้จัดการฝ่ายการตลาด อาวุโส | I16: อุ | J16: 43497
A17: 10777 | B17: 10777 | C17: Comets | D17: รัตนา | E17: มีเทียน | F17: ฝ่ายการตลาด | G17: B11_ธุรการสำนักงาน | H17: F51_เจ้าหน้าที่ธุรการ | I17: อุ้ม | J17: 44768 | K17: 44770
A18: 10962 | B18: 10962 | C18: Comets | D18: กาญจิราณ์ | E18: มณีศิริ | F18: ฝ่ายการตลาด | G18: B11_ธุรการสำนักงาน | H18: CES1_เลขานุการผู้บริหาร | I18: อ้อม | J18: 45173 | K18: 45181
A19: 11003 | B19: 11003 | C19: Comets | D19: จินดารัตน์ | E19: หงส์พัฒนานุกุล | F19: ฝ่ายการตลาด | G19: B11_ธุรการสำนักงาน | H19: CES1_เลขานุการผู้บริหาร | I19: ลักกี้ | J19: 45294 | K19: 45351
A20: 11120 | B20: 11120 | C20: Comets | D20: ศกลวรรณ | E20: เอกนันทกุล | F20: ฝ่ายการตลาด | G20: A21_การตลาด | H20: B21_เจ้าหน้าที่ฝ่ายการตลาด | I20: นุ่น | J20: 45558
A21: 11126 | B21: 11126 | C21: Comets | D21: รัชฎา | E21: แดนวงดร | F21: ฝ่ายการตลาด | G21: A21_การตลาด | H21: B21_เจ้าหน้าที่ฝ่ายการตลาด | I21: บี | J21: 45572
A22: 11127 | B22: 11127 | C22: Comets | D22: จิราพร | E22: เสียงประเสริฐ | F22: ฝ่ายการตลาด | G22: A21_การตลาด | H22: B21_เจ้าหน้าที่ฝ่ายการตลาด | I22: ฝ้าย | J22: 45580 | K22: 45683
A23: 11162 | B23: 11162 | C23: Comets | D23: จิราพร | E23: ภู่ระหงษ์ | F23: ฝ่ายการตลาด | G23: A21_การตลาด | H23: B21_เจ้าหน้าที่ฝ่ายการตลาด | I23: โดนัท | J23: 45691 | K23: 45801
A24: 11163 | B24: 11163 | C24: Comets | D24: กัลยา | E24: ภู่จันทร์ | F24: ฝ่ายการตลาด | G24: A21_การตลาด | H24: B21_เจ้าหน้าที่ฝ่ายการตลาด | I24: เบียร์ | J24: 45691 | K24: 45801
A25: 11164 | B25: 11164 | C25: Comets | D25: อักษร | E25: ปราบพินาศ | F25: ฝ่ายการตลาด | G25: A21_การตลาด | H25: B23_หัวหน้าฝ่ายการตลาด | I25: เตย | J25: 45691
A26: 30890 | B26: 30890 | C26: Comets | D26: ลลิตา | E26: คุ้มครอง | F26: ฝ่ายการตลาด | G26: A21_การตลาด | H26: B21_เจ้าหน้าที่ฝ่ายการตลาด | I26: กิ่ง | J26: 45362 | K26: 45803
A27: 11258 | B27: 11258 | C27: Comets | D27: เบญจวรรณ | E27: สอนสา | F27: ฝ่ายการตลาด | G27: A21_การตลาด | H27: B21_เจ้าหน้าที่ฝ่ายการตลาด | I27: ปูเปรี้ยว | J27: 45903
A28: 11294 | B28: 11294 | C28: Comets | D28: รัฐภูมิเพชร | E28: เจ้าอภิบริบูรณ์ | F28: ฝ่ายการตลาด | G28: A21_การตลาด | H28: B21_เจ้าหน้าที่ฝ่ายการตลาด | I28: ภูมิ | J28: 45957
A29: 10496 | B29: 10496 | C29: Comets | D29: ชินเดช | E29: จงจิรจิต | F29: พัฒนาธุรกิจและกฏหมาย | G29: A03 Business Development&Law | H29: B85_ผช.ผู้จัดการฝ่ายขายนำเสนอสินค้า | I29: ชิน | J29: 43531 | K29: 43642
A30: 10078 | B30: 10078 | C30: Comets | D30: ปัทมา | E30: ผ่องไสยศรี | F30: บัญชีและการเงิน | H30: เจ้าหน้าที่บัญชี | I30: ฝน | J30: 42395 | K30: 43330
A31: 10080 | B31: 10080 | C31: Comets | D31: พัชรินทร์ | E31: พงษ์คุณ | F31: บัญชีและการเงิน | G31: A43_การเงิน | H31: B42_เจ้าหน้าที่การเงิน อาวุโส | I31: หน่อย | J31: 42415 | K31: 43307
A32: 10101 | B32: 10101 | C32: Comets | D32: บุณยนุช | E32: ขันทองดี | F32: บัญชีและการเงิน | H32: เจ้าหน้าที่บัญชี | I32: หยก | J32: 42527 | K32: 43307
A33: 10107 | B33: 10107 | C33: Comets | D33: ดารารัตน์ | E33: ธาราแดน | F33: บัญชีและการเงิน | H33: B46_ผช.ผู้จัดการบัญชีต้นทุน อาวุโส | I33: แหม่ม | J33: 42583 | K33: 43095
A34: 9031 | B34: 9031 | C34: Comets | D34: นพกานต์ | E34: เตชะศิริเชษฐ์ | F34: บัญชีและการเงิน | H34: หัวหน้าแผนก | J34: 42111 | K34: 42880
A35: 10110 | B35: 10110 | C35: Comets | D35: สุพรรษา | E35: วงศ์ษา | F35: บัญชีและการเงิน | H35: เจ้าหน้าที่บัญชี | I35: น้ำ | J35: 42604 | K35: 43250
A36: 10111 | B36: 10111 | C36: Comets | D36: จิราพร | E36: เหล็มกาศ | F36: บัญชีและการเงิน | H36: พนักงานบัญชี อาวุโส | J36: 42614 | K36: 43126
A37: 10016 | B37: 10016 | C37: Comets | D37: ศิริรัตน์ | E37: พรมแก้วต่อ | F37: บัญชีและการเงิน | H37: พนักงานบัญชี | I37: ติ๊ก | J37: 40513 | K37: 42919
A38: 10074 | B38: 10074 | C38: Comets | D38: เบญจรงค์ | E38: วงษ์สมัย | F38: บัญชีและการเงิน | G38: A41_บัญชี | H38: B41_เจ้าหน้าที่บัญชี | I38: อ้อ | J38: 42339
A39: 10173 | B39: 10173 | C39: Comets | D39: อรรถพร | E39: กิจสมัย | F39: บัญชีและการเงิน | G39: Finance_แผนกการเงิน | H39: เจ้าหน้าที่บัญชี | J39: 42887 | K39: 43039
A40: 10259 | B40: 10259 | C40: Comets | D40: ฐิติกานต์ | E40: บริบูรณ์ | F40: บัญชีและการเงิน | G40: A41_บัญชี | H40: B41_เจ้าหน้าที่บัญชี | I40: เปียร์ | J40: 43040 | K40: 43977
...

Sheet Worklist
A1: jobType | B1: issueType | C1: อาการ
A2: คอมพิวเตอร์ | B2: Notebook | C2: หน้าจอฟ้า
A3: คอมพิวเตอร์ | B3: Notebook | C3: เครื่องเปิดไม่ติด
A4: คอมพิวเตอร์ | B4: Notebook | C4: เครื่องช้า
A5: คอมพิวเตอร์ | B5: Notebook | C5: Notebook ไม่เก็บไฟ
A6: คอมพิวเตอร์ | B6: Notebook | C6: ชาร์จไฟไม่เข้า
A7: คอมพิวเตอร์ | B7: Notebook | C7: ล็อกอินไม่ได้
A8: คอมพิวเตอร์ | B8: Notebook | C8: อื่นๆ (โปรดระบุ)
A9: คอมพิวเตอร์ | B9: PC | C9: หน้าจอฟ้า
A10: คอมพิวเตอร์ | B10: PC | C10: เครื่องเปิดไม่ติด
A11: คอมพิวเตอร์ | B11: PC | C11: เครื่องช้า
A12: คอมพิวเตอร์ | B12: PC | C12: ล็อกอินไม่ได้
... A162: ขอสิทธิ์เข้าระบบ (ทำใบขอสิทธิ์) | B162: พนักงานใหม่ | C162: อื่นๆ (โปรดระบุ)
A163: ขอสิทธิ์เข้าระบบ (ทำใบขอสิทธิ์) | B163: ขอสิทธิ์เข้าระบบ SAP
A164: ขอสิทธิ์เข้าระบบ (ทำใบขอสิทธิ์) | B164: ขอสิทธิ์เข้าระบบ Express
A165: ขอสิทธิ์เข้าระบบ (ทำใบขอสิทธิ์) | B165: เปลี่ยนแปลงสิทธิ์ (Driveshare) | C165: ขอเพิ่มสิทธิ์ไฟล์กลาง
A166: ขอสิทธิ์เข้าระบบ (ทำใบขอสิทธิ์) | B166: เปลี่ยนแปลงสิทธิ์ (Driveshare) | C166: ขอลบสิทธิ์ไฟล์กลาง
A167: ขอสิทธิ์เข้าระบบ (ทำใบขอสิทธิ์) | B167: เปลี่ยนแปลงสิทธิ์ (Driveshare) | C167: อื่นๆ (โปรดระบุ)
A168: ขอสิทธิ์เข้าระบบ (ทำใบขอสิทธิ์) | B168: เปลี่ยนแปลงสิทธิ์ (ปริ้นเตอร์) | C168: ขอเพิ่มสิทธิ์ปริ้นเตอร์ (สี)
A169: ขอสิทธิ์เข้าระบบ (ทำใบขอสิทธิ์) | B169: เปลี่ยนแปลงสิทธิ์ (ปริ้นเตอร์) | C169: ขอเพิ่มสิทธิ์ปริ้นเตอร์ (ขาว-ดำ)
A170: ขอสิทธิ์เข้าระบบ (ทำใบขอสิทธิ์) | B170: เปลี่ยนแปลงสิทธิ์ (ปริ้นเตอร์) | C170: อื่นๆ (โปรดระบุ)
A171: ขอสิทธิ์เข้าระบบ (ทำใบขอสิทธิ์) | B171: เปลี่ยนแปลงสิทธิ์ (Email) | C171: ขอเพิ่มอีเมล
A172: ขอสิทธิ์เข้าระบบ (ทำใบขอสิทธิ์) | B172: เปลี่ยนแปลงสิทธิ์ (Email) | C172: อื่นๆ (โปรดระบุ)
A173: ขอสิทธิ์เข้าระบบ (ทำใบขอสิทธิ์) | B173: ขอใช้งาน VPN
A174: ขอสิทธิ์เข้าระบบ (ทำใบขอสิทธิ์) | B174: เปลี่ยนแปลงสิทธิ์ (คอมพิวเตอร์) | C174: ขอเปลี่ยนคอมพิวเตอร์
A175: ขอสิทธิ์เข้าระบบ (ทำใบขอสิทธิ์) | B175: เปลี่ยนแปลงสิทธิ์ (คอมพิวเตอร์) | C175: ขอยืมคอมพิวเตอร์
A176: ขอสิทธิ์เข้าระบบ (ทำใบขอสิทธิ์) | B176: เปลี่ยนแปลงสิทธิ์ (คอมพิวเตอร์) | C176: อื่นๆ (โปรดระบุ)
A177: ขอสิทธิ์เข้าระบบ (ทำใบขอสิทธิ์) | B177: ขอใช้งานโปรแกรมอื่นๆ

Sheet Admin
A1: Admin | B1: Active
A2: IT01_ดุ่ย | B2: FALSE
A3: IT02_ก๊อต | B3: FALSE
A4: IT03_วี | B4: TRUE
A5: IT04_ปั้ม | B5: FALSE
A6: IT05_เอ็ม | B6: FALSE
A7: IT06_นุ | B7: FALSE
A8: IT07_ปุ๊ก | B8: TRUE
A9: IT08_แชมป์ | B9: TRUE
A10: IT09_ยาม้าล | B10: TRUE
